Workbook

Sheet How to review
A1: How to review version 3 (held-out test)
A3: Version 3 ran on 10 trials the AI had never seen. Claude graded every question; you check the shaded rows.
A5: Grades tab - RED rows (2): Claude found a problem. Type Y or N in the yellow 'Rohan agrees?' column.
A6: Grades tab - ORANGE rows (7): grades are fine, but something is worth a look (several are trial-level issues, not question errors). Type Y if you agree with the note, N if not.
A8: Needs review tab (7 rows): criteria the AI refused to turn into questions because the trial's own text is unclear or contradictory. For each, type Y if you agree it needs a human, N if you think the AI should have handled it.
A10: For your write-up: grades are an AI-assisted first pass, reviewed by a human (you).

Sheet Grades
A1: trial_id | B1: model | C1: question_number | D1: criterion_type | E1: original_text | F1: ai_question | G1: answer_that_counts_against | H1: sensitive_topic | I1: grade_level_original | J1: grade_level_question | K1: accurate (Y/N) | L1: easy to understand (Y/N) | M1: correct answer counts against (Y/N) | N1: notes | O1: flag | P1: first-pass grader | Q1: Rohan agrees? (Y/N) | R1: Rohan notes
A2: NCT05138432 | B2: study listing (no AI) | C2: 1 | D2: inclusion | E2: Maximum Age: 18 Years | F2: Are you 18 years old or younger? | G2: no | H2: no | I2: 3.7 | J2: 0.6 | K2: Y | L2: Y | M2: Y | N2: CHECK (trial level): this trial is for children 18 or younger and their families. "Are you..." is wrong if a parent is using the site | O2: check | P2: Claude | Q2: Y
A3: NCT05138432 | B3: study listing (no AI) | C3: 2 | D3: inclusion | E3: Accepts Healthy Volunteers: No · Conditions: Type 2 Diabetes | F3: Do you have type 2 diabetes (a long-term condition where your body has trouble using insulin, so your blood sugar runs high)? | G3: no | H3: no | I3: 12.6 | J3: 11.2 | K3: Y | L3: Y | M3: Y | P3: Claude
A4: NCT05138432 | B4: claude-opus-5 | C4: 3 | D4: inclusion | E4: Hemoglobin A1c greater than or equal to 6.5 | F4: Was your last hemoglobin A1c (a blood test that shows your average blood sugar over about 3 months) 6.5 or higher? | G4: no | H4: no | I4: 6.7 | J4: 5.4 | K4: Y | L4: Y | M4: Y | P4: Claude
A5: NCT05138432 | B5: claude-opus-5 | C5: 4 | D5: inclusion | E5: Receiving care at the Rady Children's Hospital Diabetes Clinic | F5: Do you get your diabetes care at the Rady Children's Hospital Diabetes Clinic? | G5: no | H5: no | I5: 12.8 | J5: 11.3 | K5: Y | L5: Y | M5: Y | P5: Claude
A6: NCT05138432 | B6: claude-opus-5 | C6: 5 | D6: exclusion | E6: Another immediate family member living in the same household who is already recruited into the study | F6: Is another immediate family member who lives in your home already taking part in this study? | G6: yes | H6: no | I6: 14.3 | J6: 11.3 | K6: Y | L6: Y | M6: Y | P6: Claude
A7: NCT07225218 | B7: study listing (no AI) | C7: 1 | D7: inclusion | E7: Minimum Age: 17 Years · Maximum Age: 25 Years | F7: Are you between 17 and 25 years old? | G7: no | H7: no | I7: 5.2 | J7: 0.8 | K7: Y | L7: Y | M7: Y | P7: Claude
A8: NCT07225218 | B8: claude-opus-5 | C8: 2 | D8: inclusion | E8: Participants who are currently enrolled (either full time or part time) as an undergraduate at UCLA and meet criteria for the T-UP Wellness Program (students who have a BMI of ≥25 (≥23 for those self- identifying as Asian) and either documented prediabetes or identified as high-risk on a CDC questionnaire). | F8: Are you currently enrolled as an undergraduate student at UCLA, either full time or part time? | G8: no | H8: no | I8: 24.4 | J8: 9.1 | K8: Y | L8: Y | M8: Y | P8: Claude
A9: NCT07225218 | B9: claude-opus-5 | C9: 3 | D9: inclusion | E9: Participants who are currently enrolled (either full time or part time) as an undergraduate at UCLA and meet criteria for the T-UP Wellness Program (students who have a BMI of ≥25 (≥23 for those self- identifying as Asian) and either documented prediabetes or identified as high-risk on a CDC questionnaire). | F9: Is your BMI (body mass index, a number based on your height and weight) 25 or higher? If you identify as Asian, is your BMI 23 or higher? | G9: no | H9: no | I9: 24.4 | J9: 5.5 | K9: Y | L9: Y | M9: Y | P9: Claude
A10: NCT07225218 | B10: claude-opus-5 | C10: 4 | D10: inclusion | E10: Participants who are currently enrolled (either full time or part time) as an undergraduate at UCLA and meet criteria for the T-UP Wellness Program (students who have a BMI of ≥25 (≥23 for those self- identifying as Asian) and either documented prediabetes or identified as high-risk on a CDC questionnaire). | F10: Do you have prediabetes (blood sugar higher than normal but not high enough to be diabetes) noted in your medical records, or were you found to be high-risk on a CDC (Centers for Disease Control and Prevention) risk questionnaire? | G10: no | H10: no | I10: 24.4 | J10: 18.7 | K10: Y | L10: Y | M10: Y | P10: Claude
A11: NCT05208164 | B11: study listing (no AI) | C11: 1 | D11: inclusion | E11: Minimum Age: 21 Years · Maximum Age: 75 Years | F11: Are you between 21 and 75 years old? | G11: no | H11: no | I11: 5.2 | J11: 0.8 | K11: Y | L11: Y | M11: Y | N11: CHECK (trial level): no "Do you have type 2 diabetes?" question here because the listing says healthy volunteers are accepted, but the criteria require type 2 diabetes. Sent to human review | O11: check | P11: Claude | Q11: Y
A12: NCT05208164 | B12: claude-opus-5 | C12: 2 | D12: inclusion | E12: Self-identifies as African American or Black | F12: Do you identify as African American or Black? | G12: no | H12: no | I12: 16.2 | J12: 11.1 | K12: Y | L12: Y | M12: Y | P12: Claude
A13: NCT05208164 | B13: claude-opus-5 | C13: 3 | D13: inclusion | E13: Valid address in greater Chicagoland area | F13: Do you have a valid home address in the greater Chicago area? | G13: no | H13: no | I13: 8.4 | J13: 7.8 | K13: Y | L13: Y | M13: Y | P13: Claude
A14: NCT05208164 | B14: claude-opus-5 | C14: 4 | D14: inclusion | E14: Mobile phone with unlimited text-messaging | F14: Do you have a mobile phone with unlimited text messaging? | G14: no | H14: no | I14: 12.3 | J14: 7.2 | K14: Y | L14: Y | M14: Y | P14: Claude
A15: NCT05208164 | B15: claude-opus-5 | C15: 5 | D15: inclusion | E15: Availability to participate in mindfulness class either in-person or online | F15: Are you available to take part in a mindfulness class (a class that teaches calm, focused attention), either in person or online? | G15: no | H15: no | I15: 16.6 | J15: 11.2 | K15: Y | L15: Y | M15: Y | P15: Claude
A16: NCT05208164 | B16: claude-opus-5 | C16: 6 | D16: exclusion | E16: Untreated obstructive sleep apnea (OSA) | F16: Do you have obstructive sleep apnea (brief stops in breathing during sleep) that is not being treated? | G16: yes | H16: no | I16: 12.3 | J16: 8.4 | K16: Y | L16: Y | M16: Y | P16: Claude
A17: NCT05208164 | B17: claude-opus-5 | C17: 7 | D17: exclusion | E17: Severe insomnia, narcolepsy, or REM sleep related disorder | F17: Do you have severe insomnia (great trouble falling or staying asleep), narcolepsy (falling asleep suddenly during the day), or a REM sleep related disorder (a problem with the dreaming stage of sleep)? | G17: yes | H17: no | I17: 15.6 | J17: 16.8 | K17: Y | L17: Y | M17: Y | P17: Claude
A18: NCT05208164 | B18: claude-opus-5 | C18: 8 | D18: exclusion | E18: Alcohol or drug abuse | F18: Do you have problems with alcohol or drug use? | G18: yes | H18: yes | I18: 6.6 | J18: 3.7 | K18: Y | L18: Y | M18: Y | P18: Claude
A19: NCT05208164 | B19: claude-opus-5 | C19: 9 | D19: exclusion | E19: Limited English proficiency | F19: Is your ability to speak and understand English limited? | G19: yes | H19: no | I19: 21 | J19: 10.2 | K19: Y | L19: Y | M19: Y | P19: Claude
A20: NCT05208164 | B20: claude-opus-5 | C20: 10 | D20: exclusion | E20: Currently engaging in mindfulness practice | F20: Do you currently have a mindfulness practice (regularly doing mindfulness or meditation)? | G20: yes | H20: no | I20: 14.7 | J20: 14.7 | K20: Y | L20: Y | M20: Y | P20: Claude
A21: NCT07032844 | B21: study listing (no AI) | C21: 1 | D21: inclusion | E21: Minimum Age: 18 Years · Maximum Age: 89 Years | F21: Are you between 18 and 89 years old? | G21: no | H21: no | I21: 5.2 | J21: 0.8 | K21: Y | L21: Y | M21: Y | P21: Claude
A22: NCT07032844 | B22: study listing (no AI) | C22: 2 | D22: inclusion | E22: Accepts Healthy Volunteers: No · Conditions: Type 2 Diabetes | F22: Do you have type 2 diabetes (a long-term condition where your body has trouble using insulin, so your blood sugar runs high)? | G22: no | H22: no | I22: 12.6 | J22: 11.2 | K22: Y | L22: Y | M22: Y | P22: Claude
A23: NCT07032844 | B23: claude-opus-5 | C23: 3 | D23: inclusion | E23: Hemoglobin A1c ≥7% within 3 months of screening | F23: Was your hemoglobin A1c (a blood test that shows your average blood sugar over the past 3 months) 7% or higher on a test done within the last 3 months? | G23: no | H23: no | I23: 6.7 | J23: 11.5 | K23: Y | L23: Y | M23: Y | P23: Claude
A24: NCT07032844 | B24: claude-opus-5 | C24: 4 | D24: inclusion | E24: Physical Disability | F24: Do you have a physical disability? | G24: no | H24: no | I24: 32.4 | J24: 10.4 | K24: Y | L24: Y | M24: Y | P24: Claude
A25: NCT07032844 | B25: claude-opus-5 | C25: 5 | D25: inclusion | E25: Must have at least 1 additional chronic conditions from the list below Hypertension Congestive Heart Failure Coronary Artery Disease Hyperlipidemia Stroke Arthritis Asthma Cancer Chronic Kidney Disease (Stages 1-4) COPD Osteoporosis Multiple Sclerosis Parkinsons | F25: Besides diabetes, do you have at least one of these health problems: high blood pressure, heart failure (heart cannot pump well), coronary artery disease (blocked heart arteries), high cholesterol, stroke, arthritis (joint pain and swelling), asthma, cancer, chronic kidney disease stages 1 to 4 (long-term kidney damage that is not end-stage), COPD (long-term lung disease that makes breathing hard), osteoporosis (thin, weak bones), multiple sclerosis (a nerve disease), or Parkinson's disease (a brain disease that affects movement)? | G25: no | H25: no | I25: 23.4 | J25: 34.1 | K25: Y | L25: N | M25: Y | N25: confusing: lists 13 health conditions in one very long question. Better as a short question with a list underneath, or a few separate questions | O25: problem | P25: Claude | Q25: Y
A26: NCT07032844 | B26: claude-opus-5 | C26: 6 | D26: exclusion | E26: Currently pregnant | F26: Are you currently pregnant? | G26: yes | H26: yes | I26: 14.7 | J26: 6.6 | K26: Y | L26: Y | M26: Y | P26: Claude
A27: NCT07032844 | B27: claude-opus-5 | C27: 7 | D27: exclusion | E27: Significant vision loss preventing use of phone/tablet for interventions | F27: Do you have major vision loss that stops you from using a phone or tablet? | G27: yes | H27: no | I27: 11.5 | J27: 5.2 | K27: Y | L27: Y | M27: Y | P27: Claude
A28: NCT07032844 | B28: claude-opus-5 | C28: 8 | D28: exclusion | E28: Received Remote Patient Monitoring or Digital Health Coaching for T2DM management within 30 days of enrollment | F28: In the last 30 days, have you taken part in remote patient monitoring (your health data sent to your care team from home) or digital health coaching for your type 2 diabetes? | G28: yes | H28: no | I28: 12.8 | J28: 13.5 | K28: Y | L28: Y | M28: Y | P28: Claude
A29: NCT07032844 | B29: claude-opus-5 | C29: 9 | D29: exclusion | E29: End-stage kidney disease (on dialysis) | F29: Do you have end-stage kidney disease and get dialysis (a treatment that cleans your blood when your kidneys cannot)? | G29: yes | H29: no | I29: 12.3 | J29: 9.2 | K29: Y | L29: Y | M29: Y | P29: Claude
A30: NCT07032844 | B30: claude-opus-5 | C30: 10 | D30: exclusion | E30: Non-english speakers | F30: Do you speak English? | G30: no | H30: no | I30: 2.9 | J30: 0.7 | K30: Y | L30: Y | M30: Y | P30: Claude
A31: NCT06028503 | B31: study listing (no AI) | C31: 1 | D31: inclusion | E31: Minimum Age: 18 Years | F31: Are you 18 years old or older? | G31: no | H31: no | I31: 3.7 | J31: 0.6 | K31: Y | L31: Y | M31: Y | P31: Claude
A32: NCT06028503 | B32: study listing (no AI) | C32: 2 | D32: inclusion | E32: Accepts Healthy Volunteers: No · Conditions: Type 2 Diabetes | F32: Do you have type 2 diabetes (a long-term condition where your body has trouble using insulin, so your blood sugar runs high)? | G32: no | H32: no | I32: 12.6 | J32: 11.2 | K32: Y | L32: Y | M32: Y | P32: Claude
A33: NCT06028503 | B33: claude-opus-5 | C33: 3 | D33: inclusion | E33: Diagnosed diabetes (self-reported) and with an HbA1c ≥ 6.0 (using point-of-care device) | F33: Is your HbA1c (a blood test showing average blood sugar over about 3 months) 6.0 or higher? | G33: no | H33: no | I33: 11.2 | J33: 4.4 | K33: Y | L33: Y | M33: Y | P33: Claude
A34: NCT06028503 | B34: claude-opus-5 | C34: 4 | D34: inclusion | E34: reliable access to a personal smartphone device 6) zip code is associated with a rural area. | F34: Do you have reliable access to your own smartphone? | G34: no | H34: no | I34: 13.5 | J34: 6.3 | K34: Y | L34: Y | M34: Y | N34: CHECK: the quote shown covers two criteria (smartphone AND rural zip code). The question is fine, but the original text shown is longer than it should be | O34: check | P34: Claude | Q34: Y
A35: NCT06028503 | B35: claude-opus-5 | C35: 5 | D35: inclusion | E35: reliable access to a personal smartphone device 6) zip code is associated with a rural area. | F35: Is your home zip code in a rural area? | G35: no | H35: no | I35: 13.5 | J35: 3.7 | K35: Y | L35: Y | M35: Y | N35: CHECK: same two-criteria quote as the row above | O35: check | P35: Claude | Q35: Y
A36: NCT06028503 | B36: claude-opus-5 | C36: 6 | D36: inclusion | E36: able to speak English | F36: Are you able to speak English? | G36: no | H36: no | I36: 3.7 | J36: 2.5 | K36: Y | L36: Y | M36: Y | P36: Claude
A37: NCT06028503 | B37: claude-opus-5 | C37: 7 | D37: exclusion | E37: has a pacemaker or other implanted electrical medical device | F37: Do you have a pacemaker (a small device placed in the chest to help control the heartbeat) or another implanted electrical medical device? | G37: yes | H37: no | I37: 14.1 | J37: 12.9 | K37: Y | L37: Y | M37: Y | P37: Claude
A38: NCT06028503 | B38: claude-opus-5 | C38: 8 | D38: exclusion | E38: Pregnant (management of diabetes while pregnant may require additional medical oversight). | F38: Are you pregnant? | G38: yes | H38: yes | I38: 17.7 | J38: 1.3 | K38: Y | L38: Y | M38: Y | P38: Claude
A39: NCT06028503 | B39: claude-opus-5 | C39: 9 | D39: exclusion | E39: uses a heavy amount of alcohol or other substances | F39: Do you drink a heavy amount of alcohol, or use a heavy amount of other substances (such as drugs)? | G39: yes | H39: yes | I39: 10.2 | J39: 9.2 | K39: Y | L39: Y | M39: Y | P39: Claude
A40: NCT07662135 | B40: study listing (no AI) | C40: 1 | D40: inclusion | E40: Minimum Age: 18 Years | F40: Are you 18 years old or older? | G40: no | H40: no | I40: 3.7 | J40: 0.6 | K40: Y | L40: Y | M40: Y | P40: Claude
...

Sheet Needs review
A1: trial_id | B1: original_text | C1: problem (written by AI) | D1: Rohan agrees it needs a human? (Y/N) | E1: Rohan notes
A2: NCT05208164 | B2: Diagnosis of type 2 diabetes | C2: The criteria require a diagnosis of type 2 diabetes, but the structured listing says the study accepts healthy volunteers. Someone should check which is correct. | D2: Y
A3: NCT07662135 | B3: HbA1c value: 1. On stable dose of SGLT2i ≥ 7.0 % to ≤ 10.5% (53 to 91.3 mmol/mol) 2. SGLT2i-naive ≥ 7.5% to ≤ 10.5% (58 to 91.3 mmol/mol) | C3: The required HbA1c range depends on whether the patient takes a stable dose of an SGLT2 inhibitor (7.0-10.5%) or has never taken one (7.5-10.5%). A single patient question cannot cover both ranges without risking a wrong exclusion; someone should decide how to split or word this. | D3: Y
A4: NCT07095543 | B4: Age 19 or older in Nebraska and Alabama. Age 21 or older in Puerto Rico. Age 18 or older in all other states. | C4: The criteria set different minimum ages depending on where the person lives (19 in Nebraska and Alabama, 21 in Puerto Rico), but the listing's minimum age is 18 years. Someone needs to check which age limit applies. | D4: Y
A5: NCT06546085 | B5: Prescribed metformin, GLP-1 agonists (oral/injectable), TZDs, DPP-IV inhibitors, Acarbose, SGLT-2 inhibitors ≥6 year. | C5: This inclusion criterion requires being prescribed these diabetes medicines for 6 years or more, but the exclusion criterion "Participants prescribed metformin, GLP-1 agonists (oral/injectable), TZDs, DPP-IV inhibitors, Acarbose, SGLT-2 inhibitors within 6 year." appears to rule out the same people. Someone needs to clarify the intended direction and time period. | D5: Y
A6: NCT06546085 | B6: Has a body mass index of 20-24.99 or 25.0-45 kg/m2. | C6: The inclusion criterion sets a lower BMI limit of 20, but the exclusion criterion rules out BMI of 18 or less, so it is unclear whether people with a BMI between 18 and 20 can join. | D6: Y
A7: NCT07778524 | B7: History of having met any of the American Diabetes Association's definitions of diabetes mellitus (i.e., overt diabetes): | C7: This criterion, and the related criterion "Laboratory evidence of diabetes mellitus:", rule out anyone with diabetes, but the trial's listed conditions include Type 2 Diabetes. Someone needs to check whether people with type 2 diabetes can take part at all. | D7: Y
A8: NCT07778524 | B8: Use of most antidiabetic medications within the 90 days prior to screening * Exceptions: thiazolidinediones, sulfonylureas, meglitinides, DPP4 inhibitors, GLP-1 receptor agonists, SGLT2 inhibitors, amylin mimetics, acarbose, insulin * Metformin is acceptable provided that recruits meet all of the inclusion criteria at screening | C8: The listed "exceptions" are themselves antidiabetic medicines, and a later criterion says antidiabetic drugs except metformin within 30 days are excluded. It is unclear which medicines and which time period actually rule a person out. | D8: Y

Sheet Summary
A1: Version 3 (held-out) | B1: claude-opus-5 | C1: study listing (no AI)
A2: Questions graded | B2: =COUNTIF(Grades!$B$2:$B$89,B$1) -> 72 | C2: =COUNTIF(Grades!$B$2:$B$89,C$1) -> 16
A3: Questions with any N | B3: =SUMPRODUCT((Grades!$B$2:$B$89=B$1)*(((Grades!$K$2:$K$89="N")+(Grades!$L$2:$L$89="N")+(Grades!$M$2:$M$89="N"))>0)) -> 2 | C3: =SUMPRODUCT((Grades!$B$2:$B$89=C$1)*(((Grades!$K$2:$K$89="N")+(Grades!$L$2:$L$89="N")+(Grades!$M$2:$M$89="N"))>0)) -> 0
A4: % fully correct | B4: =IFERROR(1-B3/B2,0) -> 0.97222222 | C4: =IFERROR(1-C3/C2,0) -> 1
A5: Accurate = N | B5: =COUNTIFS(Grades!$B$2:$B$89,B$1,Grades!$K$2:$K$89,"N") -> 1 | C5: =COUNTIFS(Grades!$B$2:$B$89,C$1,Grades!$K$2:$K$89,"N") -> 0
A6: Easy to understand = N | B6: =COUNTIFS(Grades!$B$2:$B$89,B$1,Grades!$L$2:$L$89,"N") -> 1 | C6: =COUNTIFS(Grades!$B$2:$B$89,C$1,Grades!$L$2:$L$89,"N") -> 0
A7: Counts against = N | B7: =COUNTIFS(Grades!$B$2:$B$89,B$1,Grades!$M$2:$M$89,"N") -> 0 | C7: =COUNTIFS(Grades!$B$2:$B$89,C$1,Grades!$M$2:$M$89,"N") -> 0
A8: Avg reading grade: original | B8: =AVERAGEIF(Grades!$B$2:$B$89,B$1,Grades!$I$2:$I$89) -> 12.3625 | C8: =AVERAGEIF(Grades!$B$2:$B$89,C$1,Grades!$I$2:$I$89) -> 7.9125
A9: Avg reading grade: question | B9: =AVERAGEIF(Grades!$B$2:$B$89,B$1,Grades!$J$2:$J$89) -> 9.0694444 | C9: =AVERAGEIF(Grades!$B$2:$B$89,C$1,Grades!$J$2:$J$89) -> 4.65
A10: Rows you reviewed | B10: =COUNTIFS(Grades!$B$2:$B$89,B$1,Grades!$Q$2:$Q$89,"?*") -> 5 | C10: =COUNTIFS(Grades!$B$2:$B$89,C$1,Grades!$Q$2:$Q$89,"?*") -> 4
A11: Rows you disagreed with | B11: =COUNTIFS(Grades!$B$2:$B$89,B$1,Grades!$Q$2:$Q$89,"N") -> 0 | C11: =COUNTIFS(Grades!$B$2:$B$89,C$1,Grades!$Q$2:$Q$89,"N") -> 0
A14: Opus across all three versions (AI questions, % fully correct)
B15: % fully correct | C15: questions | D15: trials
A16: Version 1 (same 10 trials) | B16: 0.83 | C16: 100 | D16: 10 tuning trials
A17: Version 2 (same 10 trials) | B17: 0.92957746 | C17: 71 | D17: 10 tuning trials
A18: Version 3 (10 NEW trials) | B18: =B4 -> 0.97222222 | C18: =B2 -> 72 | D18: 10 held-out trials
A19: Blue values come from your reviewed v1 and v2 files (Opus: 83 of 100 and 66 of 71 fully correct).
