Workbook

Sheet Grades
A1: trial_id | B1: model | C1: question_number | D1: criterion_type | E1: original_text | F1: ai_question | G1: answer_that_counts_against | H1: sensitive_topic | I1: grade_level_original | J1: grade_level_question | K1: accurate (Y/N) | L1: easy to understand (Y/N) | M1: correct answer counts against (Y/N) | N1: notes | O1: flag | P1: first-pass grader | Q1: Rohan agrees? (Y/N) | R1: Rohan notes
A2: NCT07661368 | B2: study listing (no AI) | C2: 1 | D2: inclusion | E2: Minimum Age: 50 Years · Maximum Age: 75 Years | F2: Are you between 50 and 75 years old? | G2: no | H2: no | I2: 5.2 | J2: 0.8 | K2: Y | L2: Y | M2: Y | P2: Claude
A3: NCT07661368 | B3: claude-opus-5 | C3: 2 | D3: inclusion | E3: Self-report family history of dementia or AD | F3: Does someone in your family have dementia or Alzheimer's disease (a brain illness that causes memory loss)? | G3: no | H3: no | I3: 15.8 | J3: 11.9 | K3: Y | L3: Y | M3: Y | P3: Claude
A4: NCT07661368 | B4: claude-opus-5 | C4: 3 | D4: inclusion | E4: Smartphone (iOS or Android) | F4: Do you have a smartphone (an iPhone or an Android phone)? | G4: no | H4: no | I4: 6.6 | J4: 2.6 | K4: Y | L4: Y | M4: Y | P4: Claude
A5: NCT07661368 | B5: claude-opus-5 | C5: 4 | D5: exclusion | E5: Food allergies or conditions requiring a specialized diet that would limit participation | F5: Do you have a food allergy, or a health problem that needs a special diet, that would stop you from taking part in a cooking and meal study? | G5: yes | H5: no | I5: 15.6 | J5: 10.5 | K5: Y | L5: Y | M5: Y | N5: CHECK: adds "cooking and meal study," which is not in the original text shown. Probably from the trial description - confirm it matches the trial | O5: check | P5: Claude | Q5: Y
A6: NCT07661368 | B6: claude-opus-5 | C6: 5 | D6: inclusion | E6: Score of 5 or greater on ADA (diabetes) screener | F6: Have you scored 5 or more on the ADA diabetes risk screener (a short American Diabetes Association quiz that adds up points for things like age, weight, and family history)? | G6: no | H6: no | I6: 7.6 | J6: 15.4 | K6: Y | L6: Y | M6: Y | P6: Claude
A7: NCT07661368 | B7: claude-sonnet-5 | C7: 2 | D7: inclusion | E7: Score of 5 or greater on ADA (diabetes) screener | F7: On the ADA (American Diabetes Association) diabetes risk screener, did you score 5 or higher? | G7: no | H7: no | I7: 7.6 | J7: 14.6 | K7: Y | L7: Y | M7: Y | P7: Claude
A8: NCT07661368 | B8: claude-sonnet-5 | C8: 3 | D8: inclusion | E8: Self-report family history of dementia or AD | F8: Do you have a family history of dementia or Alzheimer's disease (AD)? | G8: no | H8: no | I8: 15.8 | J8: 10.7 | K8: Y | L8: Y | M8: Y | P8: Claude
A9: NCT07661368 | B9: claude-sonnet-5 | C9: 4 | D9: inclusion | E9: Smartphone (iOS or Android) | F9: Do you have a smartphone that uses iOS (Apple) or Android? | G9: no | H9: no | I9: 6.6 | J9: 5.9 | K9: Y | L9: Y | M9: Y | P9: Claude
A10: NCT07661368 | B10: claude-sonnet-5 | C10: 5 | D10: exclusion | E10: Food allergies or conditions requiring a specialized diet that would limit participation | F10: Do you have a food allergy or a condition that needs a special diet that would limit your ability to take part in this study? | G10: yes | H10: no | I10: 15.6 | J10: 11.2 | K10: Y | L10: Y | M10: Y | P10: Claude
A11: NCT05933161 | B11: study listing (no AI) | C11: 1 | D11: inclusion | E11: Minimum Age: 18 Years | F11: Are you 18 years old or older? | G11: no | H11: no | I11: 3.7 | J11: 0.6 | K11: Y | L11: Y | M11: Y | P11: Claude
A12: NCT05933161 | B12: study listing (no AI) | C12: 2 | D12: inclusion | E12: Accepts Healthy Volunteers: No · Conditions: Type 2 Diabetes Mellitus, Hyperglycemia, Hypoglycemia | F12: Do you have type 2 diabetes (a long-term condition where your body has trouble using insulin, so your blood sugar runs high)? | G12: no | H12: no | I12: 19.8 | J12: 11.2 | K12: Y | L12: Y | M12: Y | N12: CHECK: this "from the listing" question comes from the trial's Conditions field, which is not strictly an eligibility rule. Fine for type 2 diabetes trials, but worth knowing | O12: check | P12: Claude | Q12: Y
A13: NCT05933161 | B13: claude-opus-5 | C13: 3 | D13: inclusion | E13: Prior implantation of contemporary, centrifugal flow LVAD (HeartWare or HeartMate 3) at any time after 2010 | F13: Have you had an LVAD (a heart pump implanted to help your heart pump blood) put in at any time after 2010, either a HeartWare or a HeartMate 3? | G13: no | H13: no | I13: 13.5 | J13: 10.4 | K13: Y | L13: Y | M13: Y | P13: Claude
A14: NCT05933161 | B14: claude-opus-5 | C14: 4 | D14: inclusion | E14: Greater than 3 months out from LVAD implantation | F14: Has it been more than 3 months since your LVAD (heart pump) was put in? | G14: no | H14: no | I14: 5.2 | J14: 2.1 | K14: Y | L14: Y | M14: Y | P14: Claude
A15: NCT05933161 | B15: claude-opus-5 | C15: 5 | D15: inclusion | E15: Any antihyperglycemic regimen | F15: Are you taking any medicine to lower your blood sugar (such as pills or insulin)? | G15: no | H15: no | I15: 24.9 | J15: 8.4 | K15: Y | L15: Y | M15: Y | P15: Claude
A16: NCT05933161 | B16: claude-opus-5 | C16: 6 | D16: inclusion | E16: Capable of utilizing smartphone device for LibreLink app for uploading glycemic data | F16: Are you able to use a smartphone with the LibreLink app (a phone app that uploads blood sugar readings)? | G16: no | H16: no | I16: 14.7 | J16: 8 | K16: Y | L16: Y | M16: Y | P16: Claude
A17: NCT05933161 | B17: claude-opus-5 | C17: 7 | D17: exclusion | E17: Type I diabetics | F17: Do you have type 1 diabetes (a condition where the body makes little or no insulin, usually starting in childhood)? | G17: yes | H17: no | I17: 9.2 | J17: 12.3 | K17: Y | L17: Y | M17: Y | P17: Claude
A18: NCT05933161 | B18: claude-opus-5 | C18: 8 | D18: exclusion | E18: Unable to return at 3 month evaluation | F18: Are you able to come back for a study visit at 3 months? | G18: no | H18: no | I18: 10.7 | J18: 4 | K18: Y | L18: Y | M18: Y | P18: Claude
A19: NCT05933161 | B19: claude-sonnet-5 | C19: 3 | D19: inclusion | E19: Prior implantation of contemporary, centrifugal flow LVAD (HeartWare or HeartMate 3) at any time after 2010 | F19: Do you have a HeartWare or HeartMate 3 LVAD (a mechanical pump implanted in your chest to help your heart pump blood) that was implanted after 2010? | G19: no | H19: no | I19: 13.5 | J19: 11.1 | K19: Y | L19: Y | M19: Y | P19: Claude
A20: NCT05933161 | B20: claude-sonnet-5 | C20: 4 | D20: inclusion | E20: Greater than 3 months out from LVAD implantation | F20: Was your LVAD (heart pump) implanted more than 3 months ago? | G20: no | H20: no | I20: 5.2 | J20: 3.7 | K20: Y | L20: Y | M20: Y | P20: Claude
A21: NCT05933161 | B21: claude-sonnet-5 | C21: 5 | D21: inclusion | E21: Capable of utilizing smartphone device for LibreLink app for uploading glycemic data | F21: Can you use a smartphone app, such as LibreLink, to upload blood sugar (glucose) readings? | G21: no | H21: no | I21: 14.7 | J21: 7.6 | K21: Y | L21: Y | M21: Y | P21: Claude
A22: NCT06628453 | B22: study listing (no AI) | C22: 1 | D22: inclusion | E22: Minimum Age: 18 Years · Maximum Age: 50 Years | F22: Are you between 18 and 50 years old? | G22: no | H22: no | I22: 5.2 | J22: 0.8 | K22: Y | L22: Y | M22: Y | P22: Claude
A23: NCT06628453 | B23: study listing (no AI) | C23: 2 | D23: inclusion | E23: Sexes Eligible for Study: Female | F23: Is your sex female? | G23: no | H23: no | I23: 12.3 | J23: 0.7 | K23: Y | L23: Y | M23: Y | P23: Claude
A24: NCT06628453 | B24: study listing (no AI) | C24: 3 | D24: inclusion | E24: Accepts Healthy Volunteers: No · Conditions: Type 2 Diabetes Mellitus (T2DM), Pregnancy | F24: Do you have type 2 diabetes (a long-term condition where your body has trouble using insulin, so your blood sugar runs high)? | G24: no | H24: no | I24: 14.4 | J24: 11.2 | K24: Y | L24: Y | M24: Y | P24: Claude
... A34: NCT06628453 | B34: claude-sonnet-5 | C34: 6 | D34: inclusion | E34: Type 2 diabetes mellitus treated with daily insulin injections or oral hypoglycemic agents diagnosed before pregnancy or at less than 14 weeks gestation with hemoglobin A1c 6.5% or greater | F34: Is your most recent hemoglobin A1c (a blood test that shows your average blood sugar over the past 2-3 months) 6.5% or higher? | G34: no | H34: no | I34: 13.3 | J34: 5.3 | K34: Y | L34: Y | M34: Y | P34: Claude
A35: NCT06628453 | B35: claude-sonnet-5 | C35: 7 | D35: inclusion | E35: Pregnant with viable fetus at 6 to less than 23 weeks gestation | F35: Are you currently pregnant with a viable pregnancy, and are you between 6 weeks and 23 weeks pregnant (not yet at 23 weeks)? | G35: no | H35: yes | I35: 6.8 | J35: 9.8 | K35: Y | L35: Y | M35: Y | N35: CHECK: "viable pregnancy" is not explained | O35: check | P35: Claude | Q35: Y
A36: NCT06628453 | B36: claude-sonnet-5 | C36: 8 | D36: exclusion | E36: Multiple gestation | F36: Are you pregnant with more than one baby (such as twins or triplets)? | G36: yes | H36: yes | I36: 20.6 | J36: 4 | K36: Y | L36: Y | M36: Y | P36: Claude
A37: NCT06628453 | B37: claude-sonnet-5 | C37: 9 | D37: exclusion | E37: Unable or unwilling to wear CGM due to intolerance to medical-grade adhesives or skin conditions | F37: Do you have a skin condition, or an allergy or intolerance to medical-grade adhesives, that would stop you from wearing a continuous glucose monitor (CGM, a small sensor taped to your skin that tracks blood sugar)? | G37: yes | H37: no | I37: 13.1 | J37: 17.1 | K37: Y | L37: Y | M37: Y | P37: Claude
A38: NCT06628453 | B38: claude-sonnet-5 | C38: 10 | D38: exclusion | E38: Major fetal anomaly or two or more minor fetal anomalies | F38: Has your doctor found a major problem with your baby's development (a major fetal anomaly), or two or more minor problems with your baby's development? | G38: yes | H38: yes | I38: 11.9 | J38: 14.5 | K38: Y | L38: Y | M38: Y | P38: Claude
A39: NCT05317585 | B39: study listing (no AI) | C39: 1 | D39: inclusion | E39: Minimum Age: 18 Years | F39: Are you 18 years old or older? | G39: no | H39: no | I39: 3.7 | J39: 0.6 | K39: Y | L39: Y | M39: Y | P39: Claude
A40: NCT05317585 | B40: study listing (no AI) | C40: 2 | D40: inclusion | E40: Sexes Eligible for Study: Female | F40: Is your sex female? | G40: no | H40: no | I40: 12.3 | J40: 0.7 | K40: Y | L40: Y | M40: Y | P40: Claude
A41: NCT05317585 | B41: study listing (no AI) | C41: 3 | D41: inclusion | E41: Accepts Healthy Volunteers: No · Conditions: Type 2 Diabetes Treated With Insulin, Pregnancy, High Risk | F41: Do you have type 2 diabetes (a long-term condition where your body has trouble using insulin, so your blood sugar runs high)? | G41: no | H41: no | I41: 13.5 | J41: 11.2 | K41: Y | L41: Y | M41: Y | P41: Claude
A42: NCT05317585 | B42: claude-opus-5 | C42: 4 | D42: inclusion | E42: 2) singleton gestation less than or equal to 14 weeks at initial obstetric visit | F42: Are you pregnant with one baby (not twins or more), and were you 14 weeks pregnant or less at your first pregnancy visit? | G42: no | H42: yes | I42: 10.1 | J42: 8.3 | K42: Y | L42: Y | M42: Y | P42: Claude
A43: NCT05317585 | B43: claude-opus-5 | C43: 5 | D43: inclusion | E43: 4) receiving prenatal care at UMASS Memorial Health Care (UMMHC) and plans to deliver at UMMHC | F43: Are you getting your pregnancy care at UMASS Memorial Health Care (UMMHC), and do you plan to give birth there? | G43: no | H43: yes | I43: 9.8 | J43: 8.1 | K43: Y | L43: Y | M43: Y | P43: Claude
A44: NCT05317585 | B44: claude-opus-5 | C44: 6 | D44: exclusion | E44: 1) known diagnosis of type 1 diabetes or gestational diabetes | F44: Have you been told you have type 1 diabetes (when the body makes little or no insulin) or gestational diabetes (diabetes that starts during pregnancy)? | G44: yes | H44: no | I44: 14.3 | J44: 14.9 | K44: Y | L44: Y | M44: Y | P44: Claude
A45: NCT05317585 | B45: claude-opus-5 | C45: 7 | D45: exclusion | E45: 4) multifetal gestation | F45: Are you pregnant with twins or more babies? | G45: yes | H45: yes | I45: 17 | J45: 2.3 | K45: Y | L45: Y | M45: Y | P45: Claude
A46: NCT05317585 | B46: claude-opus-5 | C46: 8 | D46: inclusion | E46: 3) established diagnosis of T2DM by laboratory criteria including hemoglobin A1c ≥6.5%, oral glucose tolerance test ≥200 mg/dL, or fasting plasma glucose ≥126 mg/dL | F46: Was your diabetes found with a lab test, such as a hemoglobin A1c (average blood sugar test) of 6.5% or higher, an oral glucose tolerance test (a drink test) of 200 mg/dL or higher, or a fasting blood sugar of 126 mg/dL or higher? | G46: no | H46: no | I46: 12.2 | J46: 9.6 | K46: Y | L46: Y | M46: Y | P46: Claude
A47: NCT05317585 | B47: claude-opus-5 | C47: 9 | D47: exclusion | E47: 2) plan to receive prenatal care or delivery outside of UMMHC | F47: Do you plan to get your pregnancy care or give birth somewhere other than UMMHC? | G47: yes | H47: yes | I47: 8 | J47: 5.2 | K47: Y | L47: Y | M47: Y | P47: Claude
... A56: NCT06739122 | B56: claude-opus-5 | C56: 4 | D56: inclusion | E56: Metformin and/or basal insulin dose must be stable for at least 8 weeks prior to screening. | F56: Has your dose of metformin and/or basal insulin (long-acting insulin) stayed the same for at least 8 weeks? | G56: no | H56: no | I56: 8.4 | J56: 9.1 | K56: Y | L56: Y | M56: Y | P56: Claude
A57: NCT06739122 | B57: claude-opus-5 | C57: 5 | D57: inclusion | E57: Have a body weight ≥50 kilograms (kg) and Body Mass Index (BMI) of >85th percentile | F57: Do you weigh at least 50 kilograms (about 110 pounds)? | G57: no | H57: no | I57: 7.6 | J57: 3.7 | K57: N | L57: Y | M57: Y | N57: missing requirement: still leaves out "BMI above the 85th percentile" (Sonnet split this into two questions and got both) | O57: problem | P57: Claude | Q57: Y
...

Sheet How to review
A1: How to review version 2
A3: Same as last time: Claude graded every question. You check the shaded rows.
A5: RED rows (12): Claude found a problem. Read original_text, ai_question and the note. Type Y or N in the yellow 'Rohan agrees?' column.
A6: ORANGE rows (4): the grades are fine, but something is worth a quick look. Type Y if you agree it's OK, N if you think it's a problem.
A7: Unshaded rows: Claude found no problems. Optional: spot-check a few.
A9: New in version 2: rows marked 'study listing (no AI)' were made by code from the trial's age, sex and conditions fields - no AI involved.
A11: The 'Summary' tab compares version 1 and version 2.
A12: Version 1 numbers include 2 corrections Claude found while grading version 2 (the bariatric-surgery exceptions). See the corrected v1 file.
A14: For your write-up: grades are an AI-assisted first pass, reviewed by a human (you).

Sheet Summary
A1: Version 2 (this file) | B1: claude-opus-5 | C1: claude-sonnet-5 | D1: study listing (no AI)
A2: Questions graded | B2: =COUNTIF(Grades!$B$2:$B$160,B$1) -> 71 | C2: =COUNTIF(Grades!$B$2:$B$160,C$1) -> 67 | D2: =COUNTIF(Grades!$B$2:$B$160,D$1) -> 21
A3: Questions with any N | B3: =SUMPRODUCT((Grades!$B$2:$B$160=B$1)*(((Grades!$K$2:$K$160="N")+(Grades!$L$2:$L$160="N")+(Grades!$M$2:$M$160="N"))>0)) -> 5 | C3: =SUMPRODUCT((Grades!$B$2:$B$160=C$1)*(((Grades!$K$2:$K$160="N")+(Grades!$L$2:$L$160="N")+(Grades!$M$2:$M$160="N"))>0)) -> 7 | D3: =SUMPRODUCT((Grades!$B$2:$B$160=D$1)*(((Grades!$K$2:$K$160="N")+(Grades!$L$2:$L$160="N")+(Grades!$M$2:$M$160="N"))>0)) -> 0
A4: % fully correct | B4: =IFERROR(1-B3/B2,0) -> 0.92957746 | C4: =IFERROR(1-C3/C2,0) -> 0.89552239 | D4: =IFERROR(1-D3/D2,0) -> 1
A5: Accurate = N | B5: =COUNTIFS(Grades!$B$2:$B$160,B$1,Grades!$K$2:$K$160,"N") -> 4 | C5: =COUNTIFS(Grades!$B$2:$B$160,C$1,Grades!$K$2:$K$160,"N") -> 6 | D5: =COUNTIFS(Grades!$B$2:$B$160,D$1,Grades!$K$2:$K$160,"N") -> 0
A6: Easy to understand = N | B6: =COUNTIFS(Grades!$B$2:$B$160,B$1,Grades!$L$2:$L$160,"N") -> 1 | C6: =COUNTIFS(Grades!$B$2:$B$160,C$1,Grades!$L$2:$L$160,"N") -> 2 | D6: =COUNTIFS(Grades!$B$2:$B$160,D$1,Grades!$L$2:$L$160,"N") -> 0
A7: Counts against = N | B7: =COUNTIFS(Grades!$B$2:$B$160,B$1,Grades!$M$2:$M$160,"N") -> 0 | C7: =COUNTIFS(Grades!$B$2:$B$160,C$1,Grades!$M$2:$M$160,"N") -> 0 | D7: =COUNTIFS(Grades!$B$2:$B$160,D$1,Grades!$M$2:$M$160,"N") -> 0
A8: Dropped qualifier | B8: =COUNTIFS(Grades!$B$2:$B$160,B$1,Grades!$N$2:$N$160,"dropped qualifier*") -> 0 | C8: =COUNTIFS(Grades!$B$2:$B$160,C$1,Grades!$N$2:$N$160,"dropped qualifier*") -> 2 | D8: =COUNTIFS(Grades!$B$2:$B$160,D$1,Grades!$N$2:$N$160,"dropped qualifier*") -> 0
A9: Missing requirement | B9: =COUNTIFS(Grades!$B$2:$B$160,B$1,Grades!$N$2:$N$160,"missing requirement*") -> 3 | C9: =COUNTIFS(Grades!$B$2:$B$160,C$1,Grades!$N$2:$N$160,"missing requirement*") -> 1 | D9: =COUNTIFS(Grades!$B$2:$B$160,D$1,Grades!$N$2:$N$160,"missing requirement*") -> 0
A10: Changed meaning | B10: =COUNTIFS(Grades!$B$2:$B$160,B$1,Grades!$N$2:$N$160,"changed meaning*") -> 1 | C10: =COUNTIFS(Grades!$B$2:$B$160,C$1,Grades!$N$2:$N$160,"changed meaning*") -> 1 | D10: =COUNTIFS(Grades!$B$2:$B$160,D$1,Grades!$N$2:$N$160,"changed meaning*") -> 0
A11: Combined criteria (new error type) | B11: =COUNTIFS(Grades!$B$2:$B$160,B$1,Grades!$N$2:$N$160,"combined criteria*") -> 0 | C11: =COUNTIFS(Grades!$B$2:$B$160,C$1,Grades!$N$2:$N$160,"combined criteria*") -> 2 | D11: =COUNTIFS(Grades!$B$2:$B$160,D$1,Grades!$N$2:$N$160,"combined criteria*") -> 0
A12: Confusing | B12: =COUNTIFS(Grades!$B$2:$B$160,B$1,Grades!$N$2:$N$160,"confusing*") -> 1 | C12: =COUNTIFS(Grades!$B$2:$B$160,C$1,Grades!$N$2:$N$160,"confusing*") -> 1 | D12: =COUNTIFS(Grades!$B$2:$B$160,D$1,Grades!$N$2:$N$160,"confusing*") -> 0
A13: Avg reading grade: original | B13: =AVERAGEIF(Grades!$B$2:$B$160,B$1,Grades!$I$2:$I$160) -> 11.766197 | C13: =AVERAGEIF(Grades!$B$2:$B$160,C$1,Grades!$I$2:$I$160) -> 11.423881 | D13: =AVERAGEIF(Grades!$B$2:$B$160,D$1,Grades!$I$2:$I$160) -> 10
A14: Avg reading grade: question | B14: =AVERAGEIF(Grades!$B$2:$B$160,B$1,Grades!$J$2:$J$160) -> 9.5605634 | C14: =AVERAGEIF(Grades!$B$2:$B$160,C$1,Grades!$J$2:$J$160) -> 10.437313 | D14: =AVERAGEIF(Grades!$B$2:$B$160,D$1,Grades!$J$2:$J$160) -> 5.2095238
A15: Rows you reviewed | B15: =COUNTIFS(Grades!$B$2:$B$160,B$1,Grades!$Q$2:$Q$160,"?*") -> 6 | C15: =COUNTIFS(Grades!$B$2:$B$160,C$1,Grades!$Q$2:$Q$160,"?*") -> 9 | D15: =COUNTIFS(Grades!$B$2:$B$160,D$1,Grades!$Q$2:$Q$160,"?*") -> 1
A16: Rows you disagreed with | B16: =COUNTIFS(Grades!$B$2:$B$160,B$1,Grades!$Q$2:$Q$160,"N") -> 0 | C16: =COUNTIFS(Grades!$B$2:$B$160,C$1,Grades!$Q$2:$Q$160,"N") -> 0 | D16: =COUNTIFS(Grades!$B$2:$B$160,D$1,Grades!$Q$2:$Q$160,"N") -> 0
A19: Version 1 vs version 2 (AI questions only)
B20: v1 fully correct | C20: v1 questions | D20: v2 fully correct | E20: v2 questions
A21: claude-opus-5 | B21: 0.83 | C21: 100 | D21: =B4 -> 0.92957746 | E21: =B2 -> 71
A22: claude-sonnet-5 | B22: 0.90909091 | C22: 77 | D22: =C4 -> 0.89552239 | E22: =C2 -> 67
A23: v1 values (blue) come from TrialFinder_step1_grades_corrected.xlsx: Opus 83 of 100, Sonnet 70 of 77 fully correct, after 2 corrections.
