Workbook

Sheet How to review
A1: How to review Claude's first-pass grades
A3: Claude filled in the three grade columns and the notes for all 177 questions. Your job is to check them.
A5: 1. Go to the "Grades" tab. Rows shaded light red are the ones Claude marked with at least one N - start there (24 rows).
A6: 2. For each red row, read "original_text", then "ai_question", then Claude's note.
A7: 3. In the yellow column "Rohan agrees? (Y/N)", type Y if you agree with Claude's grades, or N if you don't.
A8: 4. If you type N, write why in the yellow "Rohan notes" column.
A9: 5. Optional: skim a few unshaded (all-Y) rows and spot-check that they really are fine.
A11: What the grades mean
A12: accurate: does the AI question ask the same thing as the original text, with nothing missing or changed?
A13: easy to understand: would an average person understand the question without looking anything up?
A14: correct answer counts against: if a patient gave the answer in "answer_that_counts_against", should they really be turned away?
A16: Example of a filled-in review row
... A20: The "Summary" tab counts results by model and updates automatically as you edit.

Sheet Grades
A1: trial_id | B1: model | C1: question_number | D1: criterion_type | E1: original_text | F1: ai_question | G1: answer_that_counts_against | H1: sensitive_topic | I1: grade_level_original | J1: grade_level_question | K1: accurate (Y/N) | L1: easy to understand (Y/N) | M1: correct answer counts against (Y/N) | N1: notes | O1: first-pass grader | P1: Rohan agrees? (Y/N) | Q1: Rohan notes
A2: NCT07661368 | B2: claude-opus-5 | C2: 1 | D2: inclusion | E2: Age: 50 - 75 yrs | F2: Are you between 50 and 75 years old? | G2: no | H2: no | I2: -2.2 | J2: 0.8 | K2: Y | L2: Y | M2: Y | O2: Claude
A3: NCT07661368 | B3: claude-opus-5 | C3: 2 | D3: inclusion | E3: Score of 5 or greater on ADA (diabetes) screener | F3: Have you scored 5 or higher on the American Diabetes Association (ADA) diabetes risk screener? | G3: no | H3: no | I3: 7.6 | J3: 14.6 | K3: Y | L3: Y | M3: Y | O3: Claude
A4: NCT07661368 | B4: claude-opus-5 | C4: 3 | D4: inclusion | E4: Self-report family history of dementia or AD | F4: Does someone in your family have dementia or Alzheimer's disease (a brain illness that affects memory and thinking)? | G4: no | H4: no | I4: 15.8 | J4: 12.4 | K4: Y | L4: Y | M4: Y | O4: Claude
A5: NCT07661368 | B5: claude-opus-5 | C5: 4 | D5: inclusion | E5: Smartphone (iOS or Android) | F5: Do you have a smartphone (iPhone or Android)? | G5: no | H5: no | I5: 6.6 | J5: 2.3 | K5: Y | L5: Y | M5: Y | O5: Claude
A6: NCT07661368 | B6: claude-opus-5 | C6: 5 | D6: inclusion | E6: Verbal and written informed consent | F6: Are you able to give spoken and written informed consent to join a study? | G6: no | H6: no | I6: 7.6 | J6: 6.7 | K6: Y | L6: Y | M6: Y | O6: Claude
A7: NCT07661368 | B7: claude-opus-5 | C7: 6 | D7: exclusion | E7: Food allergies or conditions requiring a specialized diet that would limit participation | F7: Do you have any food allergies? | G7: yes | H7: no | I7: 15.6 | J7: 4.5 | K7: N | L7: Y | M7: Y | N7: dropped qualifier: question asks about ANY food allergy; original only excludes allergies/special diets "that would limit participation" | O7: Claude | P7: Y
A8: NCT07661368 | B8: claude-opus-5 | C8: 7 | D8: exclusion | E8: Food allergies or conditions requiring a specialized diet that would limit participation | F8: Do you have a health condition that requires you to follow a special diet? | G8: yes | H8: no | I8: 15.6 | J8: 7.6 | K8: N | L8: Y | M8: Y | N8: dropped qualifier: missing "that would limit participation" | O8: Claude | P8: Y
A9: NCT07661368 | B9: claude-sonnet-5 | C9: 1 | D9: inclusion | E9: Age: 50 - 75 yrs | F9: Are you between 50 and 75 years old? | G9: no | H9: no | I9: -2.2 | J9: 0.8 | K9: Y | L9: Y | M9: Y | O9: Claude
A10: NCT07661368 | B10: claude-sonnet-5 | C10: 2 | D10: inclusion | E10: Score of 5 or greater on ADA (diabetes) screener | F10: Did you score 5 or higher on the ADA (American Diabetes Association) diabetes risk screener? | G10: no | H10: no | I10: 7.6 | J10: 14.6 | K10: Y | L10: Y | M10: Y | O10: Claude
A11: NCT07661368 | B11: claude-sonnet-5 | C11: 3 | D11: inclusion | E11: Self-report family history of dementia or AD | F11: Do you have a family history of dementia or Alzheimer's disease? | G11: no | H11: no | I11: 15.8 | J11: 11.2 | K11: Y | L11: Y | M11: Y | O11: Claude
A12: NCT07661368 | B12: claude-sonnet-5 | C12: 4 | D12: inclusion | E12: Smartphone (iOS or Android) | F12: Do you have a smartphone (iPhone or Android)? | G12: no | H12: no | I12: 6.6 | J12: 2.3 | K12: Y | L12: Y | M12: Y | O12: Claude
A13: NCT07661368 | B13: claude-sonnet-5 | C13: 5 | D13: inclusion | E13: Verbal and written informed consent | F13: Are you willing and able to give verbal and written informed consent? | G13: no | H13: no | I13: 7.6 | J13: 6.8 | K13: Y | L13: Y | M13: Y | O13: Claude
A14: NCT07661368 | B14: claude-sonnet-5 | C14: 6 | D14: exclusion | E14: Food allergies or conditions requiring a specialized diet that would limit participation | F14: Do you have food allergies or a condition that requires a special diet that would limit your participation? | G14: yes | H14: no | I14: 15.6 | J14: 11.8 | K14: Y | L14: Y | M14: Y | O14: Claude
A15: NCT05933161 | B15: claude-opus-5 | C15: 1 | D15: inclusion | E15: Prior implantation of contemporary, centrifugal flow LVAD (HeartWare or HeartMate 3) at any time after 2010 | F15: Have you had a heart pump (LVAD, either HeartWare or HeartMate 3) implanted at any time after 2010? | G15: no | H15: no | I15: 13.5 | J15: 7.8 | K15: Y | L15: Y | M15: Y | O15: Claude
A16: NCT05933161 | B16: claude-opus-5 | C16: 2 | D16: inclusion | E16: Diagnosis of type II diabetes mellitus | F16: Have you been diagnosed with type 2 diabetes? | G16: no | H16: no | I16: 14.3 | J16: 6.7 | K16: Y | L16: Y | M16: Y | O16: Claude
A17: NCT05933161 | B17: claude-opus-5 | C17: 3 | D17: inclusion | E17: Any antihyperglycemic regimen | F17: Are you taking any medicine to lower your blood sugar? | G17: no | H17: no | I17: 24.9 | J17: 7.2 | K17: Y | L17: Y | M17: Y | O17: Claude
A18: NCT05933161 | B18: claude-opus-5 | C18: 4 | D18: inclusion | E18: Greater than 3 months out from LVAD implantation | F18: Has it been more than 3 months since your LVAD was implanted? | G18: no | H18: no | I18: 5.2 | J18: 2.9 | K18: Y | L18: Y | M18: Y | O18: Claude
A19: NCT05933161 | B19: claude-opus-5 | C19: 5 | D19: inclusion | E19: Capable of utilizing smartphone device for LibreLink app for uploading glycemic data | F19: Can you use a smartphone to run the LibreLink app and upload your blood sugar data? | G19: no | H19: no | I19: 14.7 | J19: 6.9 | K19: Y | L19: Y | M19: Y | O19: Claude
A20: NCT05933161 | B20: claude-opus-5 | C20: 6 | D20: inclusion | E20: Patients may be enrolled who have preexisting CGM in place. | F20: Do you already use a continuous glucose monitor (CGM, a sensor that tracks your blood sugar all day)? | G20: no | H20: no | I20: 6 | J20: 9.8 | K20: N | L20: Y | M20: N | N20: wrong direction: original says people who already have a CGM MAY join (allowed, not required), but a "no" answer would count against them | O20: Claude | P20: Y
A21: NCT05933161 | B21: claude-opus-5 | C21: 7 | D21: exclusion | E21: Type I diabetics | F21: Have you been diagnosed with type 1 diabetes? | G21: yes | H21: no | I21: 9.2 | J21: 6.7 | K21: Y | L21: Y | M21: Y | O21: Claude
A22: NCT05933161 | B22: claude-opus-5 | C22: 8 | D22: exclusion | E22: Unable to return at 3 month evaluation | F22: Would it be hard for you to come back for a visit 3 months later? | G22: yes | H22: no | I22: 10.7 | J22: 3.6 | K22: N | L22: Y | M22: Y | N22: dropped qualifier: "hard to come back" is broader than "unable to return" | O22: Claude | P22: Y
A23: NCT05933161 | B23: claude-sonnet-5 | C23: 1 | D23: inclusion | E23: Prior implantation of contemporary, centrifugal flow LVAD (HeartWare or HeartMate 3) at any time after 2010 | F23: Have you had a HeartWare or HeartMate 3 left ventricular assist device (LVAD) implanted at any time after 2010? | G23: no | H23: no | I23: 13.5 | J23: 10.5 | K23: Y | L23: Y | M23: Y | O23: Claude
A24: NCT05933161 | B24: claude-sonnet-5 | C24: 2 | D24: inclusion | E24: Diagnosis of type II diabetes mellitus | F24: Have you been diagnosed with type 2 diabetes? | G24: no | H24: no | I24: 14.3 | J24: 6.7 | K24: Y | L24: Y | M24: Y | O24: Claude
A25: NCT05933161 | B25: claude-sonnet-5 | C25: 3 | D25: inclusion | E25: Any antihyperglycemic regimen | F25: Are you currently taking any medicine to lower your blood sugar? | G25: no | H25: no | I25: 24.9 | J25: 9.1 | K25: Y | L25: Y | M25: Y | O25: Claude
A26: NCT05933161 | B26: claude-sonnet-5 | C26: 4 | D26: inclusion | E26: Greater than 3 months out from LVAD implantation | F26: Was your LVAD implanted more than 3 months ago? | G26: no | H26: no | I26: 5.2 | J26: 3.7 | K26: Y | L26: Y | M26: Y | O26: Claude
A27: NCT05933161 | B27: claude-sonnet-5 | C27: 5 | D27: inclusion | E27: Capable of utilizing smartphone device for LibreLink app for uploading glycemic data | F27: Do you have a smartphone you can use with the LibreLink app to upload your blood sugar data? | G27: no | H27: no | I27: 14.7 | J27: 7.2 | K27: Y | L27: Y | M27: Y | O27: Claude
A28: NCT05933161 | B28: claude-sonnet-5 | C28: 6 | D28: exclusion | E28: Type I diabetics | F28: Do you have type 1 diabetes? | G28: yes | H28: no | I28: 9.2 | J28: 4.5 | K28: Y | L28: Y | M28: Y | O28: Claude
A29: NCT05933161 | B29: claude-sonnet-5 | C29: 7 | D29: exclusion | E29: Unable to return at 3 month evaluation | F29: Would you be able to return for a follow-up visit at 3 months? | G29: no | H29: no | I29: 10.7 | J29: 5.8 | K29: Y | L29: Y | M29: Y | O29: Claude
A30: NCT06628453 | B30: claude-opus-5 | C30: 1 | D30: inclusion | E30: Type 2 diabetes mellitus treated with daily insulin injections or oral hypoglycemic agents diagnosed before pregnancy or at less than 14 weeks gestation with hemoglobin A1c 6.5% or greater | F30: Do you have type 2 diabetes treated with daily insulin shots or diabetes pills? | G30: no | H30: no | I30: 13.3 | J30: 10.1 | K30: Y | L30: Y | M30: Y | O30: Claude
A31: NCT06628453 | B31: claude-opus-5 | C31: 2 | D31: inclusion | E31: Type 2 diabetes mellitus treated with daily insulin injections or oral hypoglycemic agents diagnosed before pregnancy or at less than 14 weeks gestation with hemoglobin A1c 6.5% or greater | F31: Was your diabetes diagnosed before you became pregnant, or before 14 weeks of pregnancy? | G31: no | H31: no | I31: 13.3 | J31: 10.9 | K31: Y | L31: Y | M31: Y | O31: Claude
A32: NCT06628453 | B32: claude-opus-5 | C32: 3 | D32: inclusion | E32: Type 2 diabetes mellitus treated with daily insulin injections or oral hypoglycemic agents diagnosed before pregnancy or at less than 14 weeks gestation with hemoglobin A1c 6.5% or greater | F32: Is your A1c (a blood test showing your average blood sugar over about 3 months) 6.5% or higher? | G32: no | H32: no | I32: 13.3 | J32: 4.3 | K32: Y | L32: Y | M32: Y | O32: Claude
A33: NCT06628453 | B33: claude-opus-5 | C33: 4 | D33: inclusion | E33: Pregnant with viable fetus at 6 to less than 23 weeks gestation | F33: Are you pregnant and between 6 weeks and less than 23 weeks along? | G33: no | H33: yes | I33: 6.8 | J33: 4 | K33: Y | L33: Y | M33: Y | O33: Claude
A34: NCT06628453 | B34: claude-opus-5 | C34: 5 | D34: inclusion | E34: Maternal age 18-50 years old | F34: Are you between 18 and 50 years old? | G34: no | H34: no | I34: 2.9 | J34: 0.8 | K34: Y | L34: Y | M34: Y | O34: Claude
... A37: NCT06628453 | B37: claude-opus-5 | C37: 8 | D37: exclusion | E37: Major fetal anomaly or two or more minor fetal anomalies | F37: Have you been told your baby has a major birth defect, or two or more minor ones? | G37: yes | H37: yes | I37: 11.9 | J37: 5.6 | K37: Y | L37: Y | M37: Y | O37: Claude
A38: NCT06628453 | B38: claude-opus-5 | C38: 9 | D38: exclusion | E38: Participating in another conflicting interventional study | F38: Are you taking part in another clinical study with a treatment or device right now? | G38: yes | H38: no | I38: 24.1 | J38: 8.4 | K38: N | L38: Y | M38: Y | N38: dropped qualifier: missing "conflicting" - only studies that conflict with this one rule you out | O38: Claude | P38: Y
A39: NCT06628453 | B39: claude-opus-5 | C39: 10 | D39: exclusion | E39: Participation in this trial in a previous pregnancy | F39: Did you take part in this same trial during an earlier pregnancy? | G39: yes | H39: yes | I39: 12.6 | J39: 6.8 | K39: Y | L39: Y | M39: Y | O39: Claude
A40: NCT06628453 | B40: claude-sonnet-5 | C40: 1 | D40: inclusion | E40: Type 2 diabetes mellitus treated with daily insulin injections or oral hypoglycemic agents diagnosed before pregnancy or at less than 14 weeks gestation with hemoglobin A1c 6.5% or greater | F40: Do you have type 2 diabetes that is treated with daily insulin shots or diabetes pills? | G40: no | H40: no | I40: 13.3 | J40: 9.8 | K40: Y | L40: Y | M40: Y | O40: Claude
A41: NCT06628453 | B41: claude-sonnet-5 | C41: 2 | D41: inclusion | E41: diagnosed before pregnancy or at less than 14 weeks gestation with hemoglobin A1c 6.5% or greater | F41: Was your type 2 diabetes diagnosed before pregnancy or before 14 weeks of pregnancy? | G41: no | H41: no | I41: 7.4 | J41: 10.9 | K41: Y | L41: Y | M41: Y | O41: Claude
A42: NCT06628453 | B42: claude-sonnet-5 | C42: 3 | D42: inclusion | E42: hemoglobin A1c 6.5% or greater | F42: Is your A1c (a blood test showing your average blood sugar over about 3 months) 6.5% or higher? | G42: no | H42: no | I42: 6.6 | J42: 4.3 | K42: Y | L42: Y | M42: Y | O42: Claude
...

Sheet Summary
A1: Measure | B1: claude-opus-5 | C1: claude-sonnet-5
A2: Questions graded | B2: =COUNTIF(Grades!$B$2:$B$178,B$1) -> 100 | C2: =COUNTIF(Grades!$B$2:$B$178,C$1) -> 77
A3: Accurate = N | B3: =COUNTIFS(Grades!$B$2:$B$178,B$1,Grades!$K$2:$K$178,"N") -> 14 | C3: =COUNTIFS(Grades!$B$2:$B$178,C$1,Grades!$K$2:$K$178,"N") -> 5
A4: Easy to understand = N | B4: =COUNTIFS(Grades!$B$2:$B$178,B$1,Grades!$L$2:$L$178,"N") -> 4 | C4: =COUNTIFS(Grades!$B$2:$B$178,C$1,Grades!$L$2:$L$178,"N") -> 2
A5: Counts against = N | B5: =COUNTIFS(Grades!$B$2:$B$178,B$1,Grades!$M$2:$M$178,"N") -> 2 | C5: =COUNTIFS(Grades!$B$2:$B$178,C$1,Grades!$M$2:$M$178,"N") -> 0
A6: Questions with any N | B6: =SUMPRODUCT((Grades!$B$2:$B$178=B$1)*(((Grades!$K$2:$K$178="N")+(Grades!$L$2:$L$178="N")+(Grades!$M$2:$M$178="N"))>0)) -> 17 | C6: =SUMPRODUCT((Grades!$B$2:$B$178=C$1)*(((Grades!$K$2:$K$178="N")+(Grades!$L$2:$L$178="N")+(Grades!$M$2:$M$178="N"))>0)) -> 7
A7: % of questions fully correct | B7: =IFERROR(1-B6/B2,0) -> 0.83 | C7: =IFERROR(1-C6/C2,0) -> 0.90909091
A8: Dropped qualifier (count in notes) | B8: =COUNTIFS(Grades!$B$2:$B$178,B$1,Grades!$N$2:$N$178,"*dropped qualifier*") -> 7 | C8: =COUNTIFS(Grades!$B$2:$B$178,C$1,Grades!$N$2:$N$178,"*dropped qualifier*") -> 2
A9: Missing requirement (count in notes) | B9: =COUNTIFS(Grades!$B$2:$B$178,B$1,Grades!$N$2:$N$178,"*missing requirement*") -> 5 | C9: =COUNTIFS(Grades!$B$2:$B$178,C$1,Grades!$N$2:$N$178,"*missing requirement*") -> 2
A10: Confusing (count in notes) | B10: =COUNTIFS(Grades!$B$2:$B$178,B$1,Grades!$N$2:$N$178,"*confusing*") -> 4 | C10: =COUNTIFS(Grades!$B$2:$B$178,C$1,Grades!$N$2:$N$178,"*confusing*") -> 2
A11: Average reading grade: original | B11: =AVERAGEIF(Grades!$B$2:$B$178,B$1,Grades!$I$2:$I$178) -> 11.397 | C11: =AVERAGEIF(Grades!$B$2:$B$178,C$1,Grades!$I$2:$I$178) -> 10.727273
A12: Average reading grade: AI question | B12: =AVERAGEIF(Grades!$B$2:$B$178,B$1,Grades!$J$2:$J$178) -> 7.196 | C12: =AVERAGEIF(Grades!$B$2:$B$178,C$1,Grades!$J$2:$J$178) -> 7.4688312
A13: Rows you reviewed (agrees filled in) | B13: =COUNTIFS(Grades!$B$2:$B$178,B$1,Grades!$P$2:$P$178,"?*") -> 17 | C13: =COUNTIFS(Grades!$B$2:$B$178,C$1,Grades!$P$2:$P$178,"?*") -> 7
A14: Rows you disagreed with | B14: =COUNTIFS(Grades!$B$2:$B$178,B$1,Grades!$P$2:$P$178,"N") -> 0 | C14: =COUNTIFS(Grades!$B$2:$B$178,C$1,Grades!$P$2:$P$178,"N") -> 0
A16: Counts update automatically as you edit the Grades tab. Note counts search the notes text for the label.
